Workbook

Sheet Painel
L1: aux
B2: PAINEL DE QUANTIDADES E VALORES POR TRECHO – PR-990 | L2: x | M2: =MIN(MAX(E7+F7/20,0),Estacas!$B$650) -> 0 | N2: =MIN(MAX(E8+F8/20,0),Estacas!$B$650) -> 642.79085
B3: Rodovia PR-990 · entre a PR-364 e Rebouças · km 0+000 a 12+883,96 · Est. 0+0,00 a 642+15,817 · quantidades das memórias do projeto e valores da planilha contratual (R$ 87.300.000,00) | L3: linha | M3: =MIN(MATCH(M2,Estacas!$B$1:$B$650,1),649) -> 2 | N3: =MIN(MATCH(N2,Estacas!$B$1:$B$650,1),649) -> 649
L4: t | M4: =MIN(1,MAX(0,(M2-INDEX(Estacas!$B$1:$B$650,M3))/(INDEX(Estacas!$B$1:$B$650,M3+1)-INDEX(Estacas!$B$1:$B$650,M3)))) -> 0 | N4: =MIN(1,MAX(0,(N2-INDEX(Estacas!$B$1:$B$650,N3))/(INDEX(Estacas!$B$1:$B$650,N3+1)-INDEX(Estacas!$B$1:$B$650,N3)))) -> 1
B5: SELECIONE O TRECHO | H5: PREMISSAS (editáveis) | L5: L | M5: =INDEX('Volumes por intervalo'!$C$1:$C$650,M3) -> 20 | N5: =INDEX('Volumes por intervalo'!$C$1:$C$650,N3) -> 5.817
E6: Estaca | F6: + metros | G6: Notação | H6: 0.048 | I6: Teor de CAP executado no CBUQ (contrato 5,7%) – ajusta o item 589000 | L6: erro | N6: =IF(E8+F8/20<=E7+F7/20,"A estaca final deve ser maior que a inicial",IF(E8+F8/20>Estacas!B650+0.00001,"Estaca final além do fim do trecho (642+15,817)",""))
B7: Estaca inicial | E7: 0 | F7: 0 | G7: =E7&"+"&FIXED(F7,2) -> 0+0.00 | H7: 1.2 | I7: Taxa de EAI na imprimação (kg/m²) | L7: ext. sel. | N7: =IF($N$6<>"",0,(N2-M2)*20) -> 12855.817
B8: Estaca final | E8: 642 | F8: 15.817 | G8: =E8&"+"&FIXED(F8,2) -> 642+15.82 | H8: 0.5 | I8: Taxa de RR-1C na pintura de ligação (kg/m²) | L8: ext. total | N8: =Estacas!$B$650*20 -> 12855.817
B9: Digite só nas células amarelas. Ex.: 100 a 108 → 100 / 0 e 108 / 0 · estaca 100+10 → 100 / 10 · trecho inteiro → 0 / 0 e 642 / 15,817 | H9: =Parâmetros!$C$14 -> 2.4 | I9: Densidade do CBUQ (t/m³) – vem de Parâmetros | L9: fração | N9: =IF(N8=0,0,N7/N8) -> 1
B10: =IF($N$6="","","⚠ "&$N$6) | L10: CAP contrato | N10: 0.057
B12: RESUMO DO TRECHO | L12: full | M12: =0 -> 0 | N12: =Estacas!$B$650 -> 642.79085
B13: EXTENSÃO | E13: CBUQ | G13: CORTE (1ª+2ª+3ª) | I13: CONSUMO REAL (PROJETO) | M13: =MIN(MATCH(M12,Estacas!$B$1:$B$650,1),649) -> 2 | N13: =MIN(MATCH(N12,Estacas!$B$1:$B$650,1),649) -> 649 | P13: AJUSTADO AO CONTRATO
B14: =$N$7 -> 12855.817 | E14: =G102 -> 17868.573 | G14: =G49+G63+G68 -> 307366.46 | I14: =J478 -> 85313984 | M14: =MIN(1,MAX(0,(M12-INDEX(Estacas!$B$1:$B$650,M13))/(INDEX(Estacas!$B$1:$B$650,M13+1)-INDEX(Estacas!$B$1:$B$650,M13)))) -> 0 | N14: =MIN(1,MAX(0,(N12-INDEX(Estacas!$B$1:$B$650,N13))/(INDEX(Estacas!$B$1:$B$650,N13+1)-INDEX(Estacas!$B$1:$B$650,N13)))) -> 1 | P14: =P478 -> 87300000
B15: =G7&" → "&G8 -> 0+0.00 → 642+15.82 | E15: =FIXED(G101,0)&" m³ compactados" -> 7,445 m³ compactados | G15: volume geométrico | I15: quantidades encontradas × preço do contrato | M15: =INDEX('Volumes por intervalo'!$C$1:$C$650,M13) -> 20 | N15: =INDEX('Volumes por intervalo'!$C$1:$C$650,N13) -> 5.817 | P15: ="real − ajustado: R$ "&FIXED(J478-P478,2)&" ("&FIXED(IF(P478=0,0,(J478/P478-1)*100),1)&"%)" -> real − ajustado: R$ -1,986,016.05 (-2.3%)
B17: DADOS DO TRECHO
B18: Estaca inicial / final | E18: =G7&" → "&G8 -> 0+0.00 → 642+15.82 | G18: Seção tipo (início / fim) | I18: =INDEX(Estacas!$E$1:$E$650,M3)&" / "&INDEX(Estacas!$E$1:$E$650,N3) -> T01 / T09*
B19: Extensão | E19: =$N$7 -> 12855.817 | G19: Segmento (início / fim) | I19: =INDEX(Estacas!$D$1:$D$650,M3)&" / "&INDEX(Estacas!$D$1:$D$650,N3) -> S01 / S13
B20: Largura média do CBUQ acabado | E20: =IF(OR($N$6<>"",$N$7=0),0,((INDEX(Estacas!$S$1:$S$650,N3)+N5*N4*(2*INDEX(Estacas!$F$1:$F$650,N3)+(INDEX(Estacas!$F$1:$F$650,N3+1)-INDEX(Estacas!$F$1:$F$650,N3))*N4)/2*1)-(INDEX(Estacas!$S$1:$S$650,M3)+M5*M4*(2*INDEX(Estacas!$F$1:$F$650,M3)+(INDEX(Estacas!$F$1:$F$650,M3+1)-INDEX(Estacas!$F$1:$F$650,M3))*M4)/2*1))/$N$7) -> 11.532677 | G20: Cota de projeto (início / fim) | I20: =IF($N$6<>"","",FIXED(G483,2)&" / "&FIXED(G484,2)&" m") -> 846.29 / 796.61 m
B21: Área de CBUQ acabado | E21: =IF($N$6<>"",0,(INDEX(Estacas!$S$1:$S$650,N3)+N5*N4*(2*INDEX(Estacas!$F$1:$F$650,N3)+(INDEX(Estacas!$F$1:$F$650,N3+1)-INDEX(Estacas!$F$1:$F$650,N3))*N4)/2*1)-(INDEX(Estacas!$S$1:$S$650,M3)+M5*M4*(2*INDEX(Estacas!$F$1:$F$650,M3)+(INDEX(Estacas!$F$1:$F$650,M3+1)-INDEX(Estacas!$F$1:$F$650,M3))*M4)/2*1)) -> 148261.99 | G21: Rampa média | I21: =IF($N$6<>"","",G486/100) -> -0.0038640144
B23: RESUMO POR DISCIPLINA
B24: # | C24: Disciplina (clique para ir ao detalhe) | E24: Itens | F24: % do saldo | G24: Ajustado ao contrato (R$) | I24: Consumo real (R$) | K24: Real − ajustado
B25: 1 | C25: =HYPERLINK("#'Painel'!B42","Terraplenagem") -> Terraplenagem | E25: =COUNTIF(J43:J89,">0")&"/"&COUNT(J43:J89) -> 39/39 | F25: =IF($I$37=0,0,I25/$I$37) -> 0.20316531 | G25: =O90 -> 17469094 | I25: =J90 -> 17332842 | K25: =I25-G25 -> -136251.38
B26: 2 | C26: =HYPERLINK("#'Painel'!B92","Pavimentação") -> Pavimentação | E26: =COUNTIF(J93:J108,">0")&"/"&COUNT(J93:J108) -> 11/11 | F26: =IF($I$37=0,0,I26/$I$37) -> 0.31594894 | G26: =O109 -> 27855986 | I26: =J109 -> 26954862 | K26: =I26-G26 -> -901123.89
B27: 3 | C27: =HYPERLINK("#'Painel'!B111","Ligantes betuminosos") -> Ligantes betuminosos | E27: =COUNTIF(J112:J114,">0")&"/"&COUNT(J112:J114) -> 3/3 | F27: =IF($I$37=0,0,I27/$I$37) -> 0.07185893 | G27: =O115 -> 7400006.8 | I27: =J115 -> 6130571.6 | K27: =I27-G27 -> -1269435.2
B28: 4 | C28: =HYPERLINK("#'Painel'!B117","Drenagem e OAC") -> Drenagem e OAC | E28: =COUNTIF(J118:J261,">0")&"/"&COUNT(J118:J261) -> 68/68 | F28: =IF($I$37=0,0,I28/$I$37) -> 0.17733818 | G28: =O262 -> 16405945 | I28: =J262 -> 15129427 | K28: =I28-G28 -> -1276518.1
B29: 5 | C29: =HYPERLINK("#'Painel'!B264","Galerias e passa-fauna") -> Galerias e passa-fauna | E29: =COUNTIF(J265:J299,">0")&"/"&COUNT(J265:J299) -> 21/21 | F29: =IF($I$37=0,0,I29/$I$37) -> 0.03053132 | G29: =O300 -> 2796171.7 | I29: =J300 -> 2604748.6 | K29: =I29-G29 -> -191423.16
B30: 6 | C30: =HYPERLINK("#'Painel'!B302","OAE – ponte") -> OAE – ponte | E30: =COUNTIF(J303:J333,">0")&"/"&COUNT(J303:J333) -> 28/28 | F30: =IF($I$37=0,0,I30/$I$37) -> 0.026777918 | G30: =O334 -> 2284530.8 | I30: =J334 -> 2284530.8 | K30: =I30-G30 -> 0.0669
B31: 7 | C31: =HYPERLINK("#'Painel'!B336","Contenções") -> Contenções | E31: =COUNTIF(J337:J345,">0")&"/"&COUNT(J337:J345) -> 7/7 | F31: =IF($I$37=0,0,I31/$I$37) -> 0.0080443863 | G31: =O346 -> 687970.09 | I31: =J346 -> 686298.65 | K31: =I31-G31 -> -1671.445
B32: 8 | C32: =HYPERLINK("#'Painel'!B348","Sinalização") -> Sinalização | E32: =COUNTIF(J349:J374,">0")&"/"&COUNT(J349:J374) -> 19/19 | F32: =IF($I$37=0,0,I32/$I$37) -> 0.050910435 | G32: =O375 -> 4392206.5 | I32: =J375 -> 4343372.1 | K32: =I32-G32 -> -48834.425
B33: 9 | C33: =HYPERLINK("#'Painel'!B377","Iluminação") -> Iluminação | E33: =COUNTIF(J378:J401,">0")&"/"&COUNT(J378:J401) -> 21/21 | F33: =IF($I$37=0,0,I33/$I$37) -> 0.0031632706 | G33: =O402 -> 269878.86 | I33: =J402 -> 269871.22 | K33: =I33-G33 -> -7.644
B34: 10 | C34: =HYPERLINK("#'Painel'!B404","Paisagismo") -> Paisagismo | E34: =COUNTIF(J405:J411,">0")&"/"&COUNT(J405:J411) -> 3/3 | F34: =IF($I$37=0,0,I34/$I$37) -> 0.02557292 | G34: =O412 -> 2503353.6 | I34: =J412 -> 2181727.7 | K34: =I34-G34 -> -321625.9
B35: 11 | C35: =HYPERLINK("#'Painel'!B414","Obras complementares") -> Obras complementares | E35: =COUNTIF(J415:J442,">0")&"/"&COUNT(J415:J442) -> 25/25 | F35: =IF($I$37=0,0,I35/$I$37) -> 0.029406624 | G35: =O443 -> 2013395.8 | I35: =J443 -> 2508796.3 | K35: =I35-G35 -> 495400.46
B36: 12 | C36: =HYPERLINK("#'Painel'!B445","Serviços gerais e interferências") -> Serviços gerais e interferências | E36: =COUNTIF(J446:J475,">0")&"/"&COUNT(J446:J475) -> 24/24 | F36: =IF($I$37=0,0,I36/$I$37) -> 0.057281764 | G36: =O476 -> 3221460.9 | I36: =J476 -> 4886935.5 | K36: =I36-G36 -> 1665474.6
C37: Total | F37: =SUM(F25:F36) -> 1 | G37: =SUM(G25:G36) -> 87300000 | I37: =SUM(I25:I36) -> 85313984 | K37: =I37-G37 -> -1986016
B39: DETALHAMENTO POR SERVIÇO | E39: LE / LD / Projeto = quantidades das memórias do projeto · Contrato = quantidade contratual distribuída pelo critério da última coluna
E40: QUANTIDADES DO PROJETO | H40: CONSUMO REAL ENCONTRADO NO PROJETO | K40: AJUSTADO AO CONTRATO | Q40: DIFERENÇA
B41: Código | C41: Serviço | D41: Un | E41: LE | F41: LD | G41: Projeto no trecho | H41: Qtd. real | I41: Preço contrato (R$) | J41: Valor real (R$) | K41: Qtd. ajustada | P41: Valor ajustado (R$) | Q41: Real − ajustado (R$) | R41: Base da quantidade · critério / fonte
B42: 1 · TERRAPLENAGEM
C43: Limpeza
B44: 400000 | C44: Desmatamento e limpeza (árvores Ø até 30 cm) | D44: m² | G44: =IF($N$6<>"",0,SUMPRODUCT('Terraplenagem por estaca'!$E$2:$E$744,((('Terraplenagem por estaca'!$D$2:$D$744<$N$2)*'Terraplenagem por estaca'!$D$2:$D$744+('Terraplenagem por estaca'!$D$2:$D$744>=$N$2)*$N$2)-(('Terraplenagem por estaca'!$C$2:$C$744>$M$2)*'Terraplenagem por estaca'!$C$2:$C$744+('Terraplenagem por estaca'!$C$2:$C$744<=$M$2)*$M$2))*('Terraplenagem por estaca'!$C$2:$C$744<$N$2)*('Terraplenagem por estaca'!$D$2:$D$744>$M$2)/('Terraplenagem por estaca'!$D$2:$D$744-'Terraplenagem por estaca'!$C$2:$C$744))+SUMPRODUCT('Terrapl. – ramos e solo mole'!$E$2:$E$14,((('Terrapl. – ramos e solo mole'!$C$2:$C$14<$N$2)*'Terrapl. – ramos e solo mole'!$C$2:$C$14+('Terrapl. – ramos e solo mole'!$C$2:$C$14>=$N$2)*$N$2)-(('Terrapl. – ramos e solo mole'!$B$2:$B$14>$M$2)*'Terrapl. – ramos e solo mole'!$B$2:$B$14+('Terrapl. – ramos e solo mole'!$B$2:$B$14<=$M$2)*$M$2))*('Terrapl. – ramos e solo mole'!$B$2:$B$14<$N$2)*('Terrapl. – ramos e solo mole'!$C$2:$C$14>$M$2)/('Terrapl. – ramos e solo mole'!$C$2:$C$14-'Terrapl. – ramos e solo mole'!$B$2:$B$14))/Parâmetros!$C$22) -> 236317.35 | H44: =IF($N$6<>"",0,$G$44) -> 236317.35 | I44: 1.25 | J44: =H44*I44 -> 295396.69 | K44: =IF($N$6<>"",0,232329.7*IF($L$44=0,$N$9,$G$44/$L$44)) -> 232329.7 | L44: =SUMPRODUCT('Terraplenagem por estaca'!$E$2:$E$744,((('Terraplenagem por estaca'!$D$2:$D$744<$N$12)*'Terraplenagem por estaca'!$D$2:$D$744+('Terraplenagem por estaca'!$D$2:$D$744>=$N$12)*$N$12)-(('Terraplenagem por estaca'!$C$2:$C$744>$M$12)*'Terraplenagem por estaca'!$C$2:$C$744+('Terraplenagem por estaca'!$C$2:$C$744<=$M$12)*$M$12))*('Terraplenagem por estaca'!$C$2:$C$744<$N$12)*('Terraplenagem por estaca'!$D$2:$D$744>$M$12)/('Terraplenagem por estaca'!$D$2:$D$744-'Terraplenagem por estaca'!$C$2:$C$744))+SUMPRODUCT('Terrapl. – ramos e solo mole'!$E$2:$E$14,((('Terrapl. – ramos e solo mole'!$C$2:$C$14<$N$12)*'Terrapl. – ramos e solo mole'!$C$2:$C$14+('Terrapl. – ramos e solo mole'!$C$2:$C$14>=$N$12)*$N$12)-(('Terrapl. – ramos e solo mole'!$B$2:$B$14>$M$12)*'Terrapl. – ramos e solo mole'!$B$2:$B$14+('Terrapl. – ramos e solo mole'!$B$2:$B$14<=$M$12)*$M$12))*('Terrapl. – ramos e solo mole'!$B$2:$B$14<$N$12)*('Terrapl. – ramos e solo mole'!$C$2:$C$14>$M$12)/('Terrapl. – ramos e solo mole'!$C$2:$C$14-'Terrapl. – ramos e solo mole'!$B$2:$B$14))/Parâmetros!$C$22 -> 236317.35 | O44: =IF($N$6<>"",0,290412.12*IF($L$44=0,$N$9,$G$44/$L$44)) -> 290412.12 | P44: =O44 -> 290412.12 | Q44: =J44-P44 -> 4984.5714 | R44: Projeto · REV04 por intervalo; ramos IN-01 na Est. 326
...

Sheet Contrato × Projeto
B2: CONTRATO × PROJETO – SERVIÇOS DA PLANILHA CONTRATUAL CONFRONTADOS COM AS QUANTIDADES E CONSUMOS DOS PROJETOS
B3: Trecho inteiro 0+000 a 642+15,817 · Contrato = medição provisória ago/2026 (R$ 87.300.000,00) · Memória = total impresso nos quadros do Vol. 3 (Tomo II) e pranchas · Consumo real = apurado por estaca no Painel (atualiza com as premissas)
B5: RESUMO
B6: VALOR DO CONTRATO | F6: CONSUMO REAL A PREÇO DO CONTRATO | I6: REAL − CONTRATO | M6: SITUAÇÃO DOS ITENS | Q6: Como ler
B7: =L359 -> 87300000 | F7: =M359 -> 85313984 | I7: =N359 -> -1986016 | M7: =COUNTIF(O12:O358,"Confere*")&" conferem" -> 140 conferem | Q7: Verde = consumo real encontrado nos projetos · laranja = quantidade do contrato · amarelo na coluna "Quadro da memória" = total impresso diferente do contrato.
B8: =COUNT(F12:F358)&" itens da planilha contratual" -> 269 itens da planilha contratual | F8: projeto onde encontrado; contrato onde não | I8: =FIXED(IF(L359=0,0,N359/L359*100),1)&"% do contrato" -> -2.3% do contrato | M8: =COUNTIF(O12:O358,"Projeto maior")&" maiores · "&COUNTIF(O12:O358,"Projeto menor")&" menores · "&COUNTIF(O12:O358,"Não encontrado")&" não encontrados · "&(COUNTIF(O12:O358,"Medição mensal")+COUNTIF(O12:O358,"Mobilização"))&" mensais/mobilização" -> 29 maiores · 41 menores · 51 não encontrados · 8 mensais/mobilização | Q8: Situação: "Confere" = diferença de até ±2%. Detalhes das divergências na aba Discrepâncias; o link da última coluna leva à linha do Painel.
F10: REFERÊNCIAS | H10: CONSUMO REAL × CONTRATO | K10: VALORES A PREÇO DO CONTRATO | O10: ANÁLISE
B11: Linha med. | C11: Código | D11: Serviço | E11: Un | F11: Qtd. contrato | G11: Quadro da memória | H11: Consumo real (projeto) | I11: Real − contrato | J11: Dif. % | K11: Preço (R$) | L11: Valor contrato (R$) | M11: Valor consumo real (R$) | N11: Real − contrato (R$) | O11: Situação | P11: Como foi apurado · fonte | Q11: Discrepância / observação | R11: Painel
B12: Terraplenagem
B13: 17 | C13: 493647 | D13: Carga e transporte de material para bota fora | E13: m³ | F13: 46465.94 | G13: 46465.94 | H13: =Painel!$L$45 -> 47263.471 | I13: =IF(H13="","",H13-F13) -> 797.53062 | J13: =IF(OR(H13="",F13=0),"",H13/F13-1) -> 0.017163768 | K13: 11.78 | L13: 547368.77 | M13: =IF(H13="",F13*K13,H13*K13) -> 556763.68 | N13: =M13-L13 -> 9394.9139 | O13: =IF(F13=0,"Sem qtd. no contrato",IF(ABS(H13/F13-1)<=0.02,"Confere (±2%)",IF(H13>F13,"Projeto maior","Projeto menor"))) -> Confere (±2%) | P13: Projeto por estaca · volume de limpeza (área × 0,20 m) · memória: Quadro de terraplenagem (NCT-001) | Q13: Quadro = contrato. Por estaca (área de limpeza × 0,20 m) dá 47.263,47 m³. | R13: =HYPERLINK("#'Painel'!B45","→ 45") -> → 45
B14: 18 | C14: 400500 | D14: Colchão drenante de areia para fundação de aterros | E14: m³ | F14: 6633.83 | G14: 6633.83 | H14: =Painel!$L$82 -> 6633.825 | I14: =IF(H14="","",H14-F14) -> -0.005 | J14: =IF(OR(H14="",F14=0),"",H14/F14-1) -> -7.5371241e-07 | K14: 324.85 | L14: 2154999.7 | M14: =IF(H14="",F14*K14,H14*K14) -> 2154998.1 | N14: =M14-L14 -> -1.61875 | O14: =IF(F14=0,"Sem qtd. no contrato",IF(ABS(H14/F14-1)<=0.02,"Confere (±2%)",IF(H14>F14,"Projeto maior","Projeto menor"))) -> Confere (±2%) | P14: Projeto por estaca · 10 trechos de solo mole · memória: Quadro de terraplenagem 1.1.35 | R14: =HYPERLINK("#'Painel'!B82","→ 82") -> → 82
B15: 19 | C15: 401950 | D15: Compactação de aterros 95% PN (B) | E15: m³ | F15: 125515.05 | G15: 125515.05 | H15: =Painel!$L$78 -> 125515.05 | I15: =IF(H15="","",H15-F15) -> -0.0045417193 | J15: =IF(OR(H15="",F15=0),"",H15/F15-1) -> -3.6184659e-08 | K15: 6.18 | L15: 775683 | M15: =IF(H15="",F15*K15,H15*K15) -> 775682.98 | N15: =M15-L15 -> -0.019067826 | O15: =IF(F15=0,"Sem qtd. no contrato",IF(ABS(H15/F15-1)<=0.02,"Confere (±2%)",IF(H15>F15,"Projeto maior","Projeto menor"))) -> Confere (±2%) | P15: Projeto por estaca · REV04 por intervalo + ramos · memória: Quadro de terraplenagem 1.1.41 | R15: =HYPERLINK("#'Painel'!B78","→ 78") -> → 78
B16: 20 | C16: 401100 | D16: Compactação de aterros 100% PN (B) | E16: m³ | F16: 102477.69 | G16: 101065.34 | H16: =Painel!$L$79 -> 101065.32 | I16: =IF(H16="","",H16-F16) -> -1412.3691 | J16: =IF(OR(H16="",F16=0),"",H16/F16-1) -> -0.01378221 | K16: 7.44 | L16: 762434.01 | M16: =IF(H16="",F16*K16,H16*K16) -> 751925.99 | N16: =M16-L16 -> -10508.022 | O16: =IF(F16=0,"Sem qtd. no contrato",IF(ABS(H16/F16-1)<=0.02,"Confere (±2%)",IF(H16>F16,"Projeto maior","Projeto menor"))) -> Confere (±2%) | P16: Projeto por estaca · REV04 por intervalo + ramos · memória: Quadro de terraplenagem 1.1.40 | Q16: Contrato = quadro (101.065,34) + 1.412,35 m³. A mesma parcela de 1.412,35 m³ (preenchimento de rebaixo com material de 3ª, quadro 1.1.33) foi somada também ao 403000 e lançada como transporte 3ª cat. 400–600 m (430610). | R16: =HYPERLINK("#'Painel'!B79","→ 79") -> → 79
B17: 21 | C17: 403000 | D17: Compactação de aterros em 3a. cat. | E17: m³ | F17: 18294.23 | G17: 16881.88 | H17: =16881.88 -> 16881.88 | I17: =IF(H17="","",H17-F17) -> -1412.35 | J17: =IF(OR(H17="",F17=0),"",H17/F17-1) -> -0.077201937 | K17: 8 | L17: 146353.84 | M17: =IF(H17="",F17*K17,H17*K17) -> 135055.04 | N17: =M17-L17 -> -11298.8 | O17: =IF(F17=0,"Sem qtd. no contrato",IF(ABS(H17/F17-1)<=0.02,"Confere (±2%)",IF(H17>F17,"Projeto maior","Projeto menor"))) -> Projeto menor | P17: Total da memória (sem localização) · quadro de terraplenagem 16.881,88 m³ – distribuído pelo corte 3ª cat. · memória: Quadro de terraplenagem 1.1.38 | Q17: Contrato = quadro (16.881,88) + 1.412,35 m³ – mesma parcela somada ao 401100 e ao 430610. | R17: =HYPERLINK("#'Painel'!B80","→ 80") -> → 80
B18: 22 | C18: 400000 | D18: Desmatamento e limpeza diam. até 30cm | E18: m² | F18: 232329.7 | G18: 232329.7 | H18: =Painel!$L$44 -> 236317.35 | I18: =IF(H18="","",H18-F18) -> 3987.6531 | J18: =IF(OR(H18="",F18=0),"",H18/F18-1) -> 0.017163768 | K18: 1.25 | L18: 290412.12 | M18: =IF(H18="",F18*K18,H18*K18) -> 295396.69 | N18: =M18-L18 -> 4984.5714 | O18: =IF(F18=0,"Sem qtd. no contrato",IF(ABS(H18/F18-1)<=0.02,"Confere (±2%)",IF(H18>F18,"Projeto maior","Projeto menor"))) -> Confere (±2%) | P18: Projeto por estaca · REV04 por intervalo; ramos IN-01 na Est. 326 · memória: Quadro de terraplenagem 1.1.1 | R18: =HYPERLINK("#'Painel'!B44","→ 44") -> → 44
B19: 23 | C19: 400300 | D19: Destocamento árvores diam. > 30cm | E19: un | F19: 259 | G19: 259 | H19: =(Painel!$L$46)*1 -> 259 | I19: =IF(H19="","",H19-F19) -> 0 | J19: =IF(OR(H19="",F19=0),"",H19/F19-1) -> 0 | K19: 54.77 | L19: 14185.43 | M19: =IF(H19="",F19*K19,H19*K19) -> 14185.43 | N19: =M19-L19 -> 0 | O19: =IF(F19=0,"Sem qtd. no contrato",IF(ABS(H19/F19-1)<=0.02,"Confere (±2%)",IF(H19>F19,"Projeto maior","Projeto menor"))) -> Confere (±2%) | P19: Projeto por estaca – grupo repartido na proporção do contrato · árvores do projeto de interferências (IT-2-0001) · memória: IT-2-0001 – resumo 3.1 | Q19: Projeto de interferências IT-2-0001: 85 exóticas + 174 nativas = 259 árvores (= contrato), localizadas por coordenada. O paisagismo PG-01 só marca 16 delas na planta. | R19: =HYPERLINK("#'Painel'!B47","→ 47") -> → 47
B20: 24 | C20: 410200 | D20: Esc. carga e transp. 1a. cat. 0-200m | E20: m³ | F20: 101294.29 | G20: 101294.29 | H20: =(Painel!$L$49)*0.38667268 -> 99858.75 | I20: =IF(H20="","",H20-F20) -> -1435.5399 | J20: =IF(OR(H20="",F20=0),"",H20/F20-1) -> -0.014171972 | K20: 10.47 | L20: 1060551.2 | M20: =IF(H20="",F20*K20,H20*K20) -> 1045521.1 | N20: =M20-L20 -> -15030.096 | O20: =IF(F20=0,"Sem qtd. no contrato",IF(ABS(H20/F20-1)<=0.02,"Confere (±2%)",IF(H20>F20,"Projeto maior","Projeto menor"))) -> Confere (±2%) | P20: Projeto por estaca – grupo repartido na proporção do contrato · corte 1ª cat. do projeto × participação da faixa de DMT no contrato · memória: Quadro de terraplenagem (mesma faixa de DMT) | Q20: Corte 1ª cat. por estaca (REV04 + ramos) repartido entre as faixas na proporção do contrato: −1,4% em todas as faixas. | R20: =HYPERLINK("#'Painel'!B50","→ 50") -> → 50
B21: 25 | C21: 410400 | D21: Esc. carga e transp. 1a. cat. 200-400m | E21: m³ | F21: 13280.16 | G21: 13280.16 | H21: =(Painel!$L$49)*0.05069461 -> 13091.953 | I21: =IF(H21="","",H21-F21) -> -188.20742 | J21: =IF(OR(H21="",F21=0),"",H21/F21-1) -> -0.014172074 | K21: 10.76 | L21: 142894.52 | M21: =IF(H21="",F21*K21,H21*K21) -> 140869.41 | N21: =M21-L21 -> -2025.1102 | O21: =IF(F21=0,"Sem qtd. no contrato",IF(ABS(H21/F21-1)<=0.02,"Confere (±2%)",IF(H21>F21,"Projeto maior","Projeto menor"))) -> Confere (±2%) | P21: Projeto por estaca – grupo repartido na proporção do contrato · corte 1ª cat. do projeto × participação da faixa de DMT no contrato · memória: Quadro de terraplenagem (mesma faixa de DMT) | Q21: Corte 1ª cat. por estaca (REV04 + ramos) repartido entre as faixas na proporção do contrato: −1,4% em todas as faixas. | R21: =HYPERLINK("#'Painel'!B51","→ 51") -> → 51
B22: 26 | C22: 410800 | D22: Esc. carga e transp. 1a. cat. 600-800m | E22: m³ | F22: 4653.93 | G22: 4653.93 | H22: =(Painel!$L$49)*0.01776554 -> 4587.9751 | I22: =IF(H22="","",H22-F22) -> -65.954921 | J22: =IF(OR(H22="",F22=0),"",H22/F22-1) -> -0.014171876 | K22: 11.55 | L22: 53752.89 | M22: =IF(H22="",F22*K22,H22*K22) -> 52991.112 | N22: =M22-L22 -> -761.77784 | O22: =IF(F22=0,"Sem qtd. no contrato",IF(ABS(H22/F22-1)<=0.02,"Confere (±2%)",IF(H22>F22,"Projeto maior","Projeto menor"))) -> Confere (±2%) | P22: Projeto por estaca – grupo repartido na proporção do contrato · corte 1ª cat. do projeto × participação da faixa de DMT no contrato · memória: Quadro de terraplenagem (mesma faixa de DMT) | Q22: Corte 1ª cat. por estaca (REV04 + ramos) repartido entre as faixas na proporção do contrato: −1,4% em todas as faixas. | R22: =HYPERLINK("#'Painel'!B52","→ 52") -> → 52
B23: 27 | C23: 411000 | D23: Esc. carga e transp. 1a. cat. 800-1000m | E23: m³ | F23: 1642.77 | G23: 1642.77 | H23: =(Painel!$L$49)*0.00627098 -> 1619.4892 | I23: =IF(H23="","",H23-F23) -> -23.280811 | J23: =IF(OR(H23="",F23=0),"",H23/F23-1) -> -0.01417168 | K23: 11.99 | L23: 19696.81 | M23: =IF(H23="",F23*K23,H23*K23) -> 19417.675 | N23: =M23-L23 -> -279.13463 | O23: =IF(F23=0,"Sem qtd. no contrato",IF(ABS(H23/F23-1)<=0.02,"Confere (±2%)",IF(H23>F23,"Projeto maior","Projeto menor"))) -> Confere (±2%) | P23: Projeto por estaca – grupo repartido na proporção do contrato · corte 1ª cat. do projeto × participação da faixa de DMT no contrato · memória: Quadro de terraplenagem (mesma faixa de DMT) | Q23: Corte 1ª cat. por estaca (REV04 + ramos) repartido entre as faixas na proporção do contrato: −1,4% em todas as faixas. | R23: =HYPERLINK("#'Painel'!B53","→ 53") -> → 53
B24: 28 | C24: 411200 | D24: Esc. carga e transp. 1a. cat. 1000-1200m | E24: m³ | F24: 19198.55 | G24: 19198.55 | H24: =(Painel!$L$49)*0.073287 -> 18926.468 | I24: =IF(H24="","",H24-F24) -> -272.0817 | J24: =IF(OR(H24="",F24=0),"",H24/F24-1) -> -0.014171992 | K24: 12.38 | L24: 237678.04 | M24: =IF(H24="",F24*K24,H24*K24) -> 234309.68 | N24: =M24-L24 -> -3368.3625 | O24: =IF(F24=0,"Sem qtd. no contrato",IF(ABS(H24/F24-1)<=0.02,"Confere (±2%)",IF(H24>F24,"Projeto maior","Projeto menor"))) -> Confere (±2%) | P24: Projeto por estaca – grupo repartido na proporção do contrato · corte 1ª cat. do projeto × participação da faixa de DMT no contrato · memória: Quadro de terraplenagem (mesma faixa de DMT) | Q24: Corte 1ª cat. por estaca (REV04 + ramos) repartido entre as faixas na proporção do contrato: −1,4% em todas as faixas. | R24: =HYPERLINK("#'Painel'!B54","→ 54") -> → 54
B25: 29 | C25: 411400 | D25: Esc. carga e transp. 1a. cat. 1200-1400m | E25: m³ | F25: 5665.84 | G25: 5665.84 | H25: =(Painel!$L$49)*0.02162832 -> 5585.5433 | I25: =IF(H25="","",H25-F25) -> -80.296686 | J25: =IF(OR(H25="",F25=0),"",H25/F25-1) -> -0.014172071 | K25: 13.71 | L25: 77678.66 | M25: =IF(H25="",F25*K25,H25*K25) -> 76577.799 | N25: =M25-L25 -> -1100.8612 | O25: =IF(F25=0,"Sem qtd. no contrato",IF(ABS(H25/F25-1)<=0.02,"Confere (±2%)",IF(H25>F25,"Projeto maior","Projeto menor"))) -> Confere (±2%) | P25: Projeto por estaca – grupo repartido na proporção do contrato · corte 1ª cat. do projeto × participação da faixa de DMT no contrato · memória: Quadro de terraplenagem (mesma faixa de DMT) | Q25: Corte 1ª cat. por estaca (REV04 + ramos) repartido entre as faixas na proporção do contrato: −1,4% em todas as faixas. | R25: =HYPERLINK("#'Painel'!B55","→ 55") -> → 55
B26: 30 | C26: 411600 | D26: Esc. carga e transp. 1a. cat. 1400-1600m | E26: m³ | F26: 601.86 | G26: 601.86 | H26: =(Painel!$L$49)*0.00229749 -> 593.32994 | I26: =IF(H26="","",H26-F26) -> -8.5300554 | J26: =IF(OR(H26="",F26=0),"",H26/F26-1) -> -0.014172823 | K26: 14.16 | L26: 8522.33 | M26: =IF(H26="",F26*K26,H26*K26) -> 8401.552 | N26: =M26-L26 -> -120.77798 | O26: =IF(F26=0,"Sem qtd. no contrato",IF(ABS(H26/F26-1)<=0.02,"Confere (±2%)",IF(H26>F26,"Projeto maior","Projeto menor"))) -> Confere (±2%) | P26: Projeto por estaca – grupo repartido na proporção do contrato · corte 1ª cat. do projeto × participação da faixa de DMT no contrato · memória: Quadro de terraplenagem (mesma faixa de DMT) | Q26: Corte 1ª cat. por estaca (REV04 + ramos) repartido entre as faixas na proporção do contrato: −1,4% em todas as faixas. | R26: =HYPERLINK("#'Painel'!B56","→ 56") -> → 56
B27: 31 | C27: 412000 | D27: Esc. carga e transp. 1a. cat. 1600-2000m | E27: m³ | F27: 6926.57 | G27: 6926.57 | H27: =(Painel!$L$49)*0.02644093 -> 6828.4064 | I27: =IF(H27="","",H27-F27) -> -98.163551 | J27: =IF(OR(H27="",F27=0),"",H27/F27-1) -> -0.014172029 | K27: 14.9 | L27: 103205.89 | M27: =IF(H27="",F27*K27,H27*K27) -> 101743.26 | N27: =M27-L27 -> -1462.6339 | O27: =IF(F27=0,"Sem qtd. no contrato",IF(ABS(H27/F27-1)<=0.02,"Confere (±2%)",IF(H27>F27,"Projeto maior","Projeto menor"))) -> Confere (±2%) | P27: Projeto por estaca – grupo repartido na proporção do contrato · corte 1ª cat. do projeto × participação da faixa de DMT no contrato · memória: Quadro de terraplenagem (mesma faixa de DMT) | Q27: Corte 1ª cat. por estaca (REV04 + ramos) repartido entre as faixas na proporção do contrato: −1,4% em todas as faixas. | R27: =HYPERLINK("#'Painel'!B57","→ 57") -> → 57
B28: 32 | C28: 413000 | D28: Esc. carga e transp. 1a. cat. 2000-3000m | E28: m³ | F28: 17218.97 | G28: 17218.97 | H28: =(Painel!$L$49)*0.06573031 -> 16974.943 | I28: =IF(H28="","",H28-F28) -> -244.02726 | J28: =IF(OR(H28="",F28=0),"",H28/F28-1) -> -0.014172001 | K28: 17.21 | L28: 296338.47 | M28: =IF(H28="",F28*K28,H28*K28) -> 292138.76 | N28: =M28-L28 -> -4199.7055 | O28: =IF(F28=0,"Sem qtd. no contrato",IF(ABS(H28/F28-1)<=0.02,"Confere (±2%)",IF(H28>F28,"Projeto maior","Projeto menor"))) -> Confere (±2%) | P28: Projeto por estaca – grupo repartido na proporção do contrato · corte 1ª cat. do projeto × participação da faixa de DMT no contrato · memória: Quadro de terraplenagem (mesma faixa de DMT) | Q28: Corte 1ª cat. por estaca (REV04 + ramos) repartido entre as faixas na proporção do contrato: −1,4% em todas as faixas. | R28: =HYPERLINK("#'Painel'!B58","→ 58") -> → 58
B29: 33 | C29: 414000 | D29: Esc. carga e transp. 1a. cat. 3000-4000m | E29: m³ | F29: 34344.1 | G29: 34344.1 | H29: =(Painel!$L$49)*0.13110241 -> 33857.377 | I29: =IF(H29="","",H29-F29) -> -486.72275 | J29: =IF(OR(H29="",F29=0),"",H29/F29-1) -> -0.014171946 | K29: 19.27 | L29: 661810.8 | M29: =IF(H29="",F29*K29,H29*K29) -> 652431.66 | N29: =M29-L29 -> -9379.1403 | O29: =IF(F29=0,"Sem qtd. no contrato",IF(ABS(H29/F29-1)<=0.02,"Confere (±2%)",IF(H29>F29,"Projeto maior","Projeto menor"))) -> Confere (±2%) | P29: Projeto por estaca – grupo repartido na proporção do contrato · corte 1ª cat. do projeto × participação da faixa de DMT no contrato · memória: Quadro de terraplenagem (mesma faixa de DMT) | Q29: Corte 1ª cat. por estaca (REV04 + ramos) repartido entre as faixas na proporção do contrato: −1,4% em todas as faixas. | R29: =HYPERLINK("#'Painel'!B59","→ 59") -> → 59
B30: 34 | C30: 415000 | D30: Esc. carga e transp. 1a. cat. 4000-5000m | E30: m³ | F30: 39996.26 | G30: 39996.26 | H30: =(Painel!$L$49)*0.15267851 -> 39429.435 | I30: =IF(H30="","",H30-F30) -> -566.82532 | J30: =IF(OR(H30="",F30=0),"",H30/F30-1) -> -0.014171958 | K30: 22.25 | L30: 889916.78 | M30: =IF(H30="",F30*K30,H30*K30) -> 877304.92 | N30: =M30-L30 -> -12611.858 | O30: =IF(F30=0,"Sem qtd. no contrato",IF(ABS(H30/F30-1)<=0.02,"Confere (±2%)",IF(H30>F30,"Projeto maior","Projeto menor"))) -> Confere (±2%) | P30: Projeto por estaca – grupo repartido na proporção do contrato · corte 1ª cat. do projeto × participação da faixa de DMT no contrato · memória: Quadro de terraplenagem (mesma faixa de DMT) | Q30: Corte 1ª cat. por estaca (REV04 + ramos) repartido entre as faixas na proporção do contrato: −1,4% em todas as faixas. | R30: =HYPERLINK("#'Painel'!B60","→ 60") -> → 60
B31: 35 | C31: 416010 | D31: Esc. carga e transp. 1a. cat. 5000-6000m | E31: m³ | F31: 13777.85 | G31: 13777.85 | H31: =(Painel!$L$49)*0.05259446 -> 13582.591 | I31: =IF(H31="","",H31-F31) -> -195.25855 | J31: =IF(OR(H31="",F31=0),"",H31/F31-1) -> -0.014171917 | K31: 25.37 | L31: 349544.05 | M31: =IF(H31="",F31*K31,H31*K31) -> 344590.35 | N31: =M31-L31 -> -4953.7048 | O31: =IF(F31=0,"Sem qtd. no contrato",IF(ABS(H31/F31-1)<=0.02,"Confere (±2%)",IF(H31>F31,"Projeto maior","Projeto menor"))) -> Confere (±2%) | P31: Projeto por estaca – grupo repartido na proporção do contrato · corte 1ª cat. do projeto × participação da faixa de DMT no contrato · memória: Quadro de terraplenagem (mesma faixa de DMT) | Q31: Corte 1ª cat. por estaca (REV04 + ramos) repartido entre as faixas na proporção do contrato: −1,4% em todas as faixas. | R31: =HYPERLINK("#'Painel'!B61","→ 61") -> → 61
B32: 36 | C32: 418000 | D32: Esc. carga e transp. 1a. cat. 6000-8000m | E32: m³ | F32: 3362.77 | G32: 3362.77 | H32: =(Painel!$L$49)*0.01283677 -> 3315.1135 | I32: =IF(H32="","",H32-F32) -> -47.656536 | J32: =IF(OR(H32="",F32=0),"",H32/F32-1) -> -0.014171809 | K32: 29.3 | L32: 98529.16 | M32: =IF(H32="",F32*K32,H32*K32) -> 97132.825 | N32: =M32-L32 -> -1396.3355 | O32: =IF(F32=0,"Sem qtd. no contrato",IF(ABS(H32/F32-1)<=0.02,"Confere (±2%)",IF(H32>F32,"Projeto maior","Projeto menor"))) -> Confere (±2%) | P32: Projeto por estaca – grupo repartido na proporção do contrato · corte 1ª cat. do projeto × participação da faixa de DMT no contrato · memória: Quadro de terraplenagem (mesma faixa de DMT) | Q32: Corte 1ª cat. por estaca (REV04 + ramos) repartido entre as faixas na proporção do contrato: −1,4% em todas as faixas. | R32: =HYPERLINK("#'Painel'!B62","→ 62") -> → 62
B33: 37 | C33: 420400 | D33: Esc. carga e transp. 2a. cat. 200-400m | E33: m³ | F33: 5535 | G33: 5535 | H33: =(Painel!$L$63)*0.17495017 -> 5535 | I33: =IF(H33="","",H33-F33) -> -6.1139963e-07 | J33: =IF(OR(H33="",F33=0),"",H33/F33-1) -> -1.1046064e-10 | K33: 14.84 | L33: 82139.4 | M33: =IF(H33="",F33*K33,H33*K33) -> 82139.4 | N33: =M33-L33 -> -9.0731628e-06 | O33: =IF(F33=0,"Sem qtd. no contrato",IF(ABS(H33/F33-1)<=0.02,"Confere (±2%)",IF(H33>F33,"Projeto maior","Projeto menor"))) -> Confere (±2%) | P33: Projeto por estaca – grupo repartido na proporção do contrato · corte 2ª cat. do projeto × participação da faixa de DMT no contrato · memória: Quadro de terraplenagem (mesma faixa de DMT) | Q33: Corte 2ª cat. por estaca = quadro = contrato (31.637,58 m³). | R33: =HYPERLINK("#'Painel'!B64","→ 64") -> → 64
B34: 38 | C34: 420800 | D34: Esc. carga e transp. 2a. cat. 600-800m | E34: m³ | F34: 267.12 | G34: 267.12 | H34: =(Painel!$L$63)*0.00844312 -> 267.11988 | I34: =IF(H34="","",H34-F34) -> -0.0001155504 | J34: =IF(OR(H34="",F34=0),"",H34/F34-1) -> -4.3257862e-07 | K34: 15.81 | L34: 4223.16 | M34: =IF(H34="",F34*K34,H34*K34) -> 4223.1654 | N34: =M34-L34 -> 0.0053731482 | O34: =IF(F34=0,"Sem qtd. no contrato",IF(ABS(H34/F34-1)<=0.02,"Confere (±2%)",IF(H34>F34,"Projeto maior","Projeto menor"))) -> Confere (±2%) | P34: Projeto por estaca – grupo repartido na proporção do contrato · corte 2ª cat. do projeto × participação da faixa de DMT no contrato · memória: Quadro de terraplenagem (mesma faixa de DMT) | Q34: Corte 2ª cat. por estaca = quadro = contrato (31.637,58 m³). | R34: =HYPERLINK("#'Painel'!B65","→ 65") -> → 65
B35: 39 | C35: 422000 | D35: Esc. carga e transp. 2a. cat. 1600-2000m | E35: m³ | F35: 8489.19 | G35: 8489.19 | H35: =(Painel!$L$63)*0.26832615 -> 8489.19 | I35: =IF(H35="","",H35-F35) -> 3.6717e-05 | J35: =IF(OR(H35="",F35=0),"",H35/F35-1) -> 4.3251476e-09 | K35: 19.99 | L35: 169698.9 | M35: =IF(H35="",F35*K35,H35*K35) -> 169698.91 | N35: =M35-L35 -> 0.0088339728 | O35: =IF(F35=0,"Sem qtd. no contrato",IF(ABS(H35/F35-1)<=0.02,"Confere (±2%)",IF(H35>F35,"Projeto maior","Projeto menor"))) -> Confere (±2%) | P35: Projeto por estaca – grupo repartido na proporção do contrato · corte 2ª cat. do projeto × participação da faixa de DMT no contrato · memória: Quadro de terraplenagem (mesma faixa de DMT) | Q35: Corte 2ª cat. por estaca = quadro = contrato (31.637,58 m³). | R35: =HYPERLINK("#'Painel'!B66","→ 66") -> → 66
B36: 40 | C36: 423000 | D36: Esc. carga e transp. 2a. cat. 2000-3000m | E36: m³ | F36: 17346.27 | G36: 17346.27 | H36: =(Painel!$L$63)*0.54828056 -> 17346.27 | I36: =IF(H36="","",H36-F36) -> 7.9444802e-05 | J36: =IF(OR(H36="",F36=0),"",H36/F36-1) -> 4.5799358e-09 | K36: 21.84 | L36: 378842.53 | M36: =IF(H36="",F36*K36,H36*K36) -> 378842.54 | N36: =M36-L36 -> 0.0085350745 | O36: =IF(F36=0,"Sem qtd. no contrato",IF(ABS(H36/F36-1)<=0.02,"Confere (±2%)",IF(H36>F36,"Projeto maior","Projeto menor"))) -> Confere (±2%) | P36: Projeto por estaca – grupo repartido na proporção do contrato · corte 2ª cat. do projeto × participação da faixa de DMT no contrato · memória: Quadro de terraplenagem (mesma faixa de DMT) | Q36: Corte 2ª cat. por estaca = quadro = contrato (31.637,58 m³). | R36: =HYPERLINK("#'Painel'!B67","→ 67") -> → 67
B37: 41 | C37: 430410 | D37: Esc. carga e transp. 3a. cat. 200-400m | E37: m³ | F37: 2271.55 | G37: 2271.55 | H37: =(Painel!$L$68)*0.15776395 -> 2757.3213 | I37: =IF(H37="","",H37-F37) -> 485.77125 | J37: =IF(OR(H37="",F37=0),"",H37/F37-1) -> 0.21385012 | K37: 46.71 | L37: 106104.1 | M37: =IF(H37="",F37*K37,H37*K37) -> 128794.48 | N37: =M37-L37 -> 22690.376 | O37: =IF(F37=0,"Sem qtd. no contrato",IF(ABS(H37/F37-1)<=0.02,"Confere (±2%)",IF(H37>F37,"Projeto maior","Projeto menor"))) -> Projeto maior | P37: Projeto por estaca – grupo repartido na proporção do contrato · corte 3ª cat. do projeto × participação da faixa de DMT no contrato · memória: Quadro de terraplenagem (mesma faixa de DMT) | Q37: Corte 3ª cat. por estaca: 17.477,51 m³ contra 14.398,41 m³ das faixas do contrato (+21,4%), repartido na proporção do contrato. Note que o quadro soma 12.986,06 m³ sem o 430610. | R37: =HYPERLINK("#'Painel'!B69","→ 69") -> → 69
B38: 42 | C38: 430610 | D38: Esc. carga e transp. 3a. cat. 400-600m | E38: m³ | F38: 1412.35 | G38: 0 | H38: =(Painel!$L$68)*0.09809069 -> 1714.3812 | I38: =IF(H38="","",H38-F38) -> 302.03116 | J38: =IF(OR(H38="",F38=0),"",H38/F38-1) -> 0.21385008 | K38: 48.32 | L38: 68244.75 | M38: =IF(H38="",F38*K38,H38*K38) -> 82838.898 | N38: =M38-L38 -> 14594.148 | O38: =IF(F38=0,"Sem qtd. no contrato",IF(ABS(H38/F38-1)<=0.02,"Confere (±2%)",IF(H38>F38,"Projeto maior","Projeto menor"))) -> Projeto maior | P38: Projeto por estaca – grupo repartido na proporção do contrato · corte 3ª cat. do projeto × participação da faixa de DMT no contrato · memória: Faixa 400–600 m inexistente no quadro de terraplenagem | Q38: Faixa de DMT que não existe no quadro de terraplenagem; os 1.412,35 m³ são o preenchimento de rebaixo com material de 3ª (quadro 1.1.33), que já está no 495161. | R38: =HYPERLINK("#'Painel'!B70","→ 70") -> → 70
B39: 43 | C39: 431410 | D39: Esc. carga e transp. 3a. cat. 1200-1400m | E39: m³ | F39: 435.13 | G39: 435.13 | H39: =(Painel!$L$68)*0.0302207 -> 528.18263 | I39: =IF(H39="","",H39-F39) -> 93.052632 | J39: =IF(OR(H39="",F39=0),"",H39/F39-1) -> 0.21385019 | K39: 50.52 | L39: 21982.76 | M39: =IF(H39="",F39*K39,H39*K39) -> 26683.787 | N39: =M39-L39 -> 4701.0266 | O39: =IF(F39=0,"Sem qtd. no contrato",IF(ABS(H39/F39-1)<=0.02,"Confere (±2%)",IF(H39>F39,"Projeto maior","Projeto menor"))) -> Projeto maior | P39: Projeto por estaca – grupo repartido na proporção do contrato · corte 3ª cat. do projeto × participação da faixa de DMT no contrato · memória: Quadro de terraplenagem (mesma faixa de DMT) | Q39: Corte 3ª cat. por estaca: 17.477,51 m³ contra 14.398,41 m³ das faixas do contrato (+21,4%), repartido na proporção do contrato. Note que o quadro soma 12.986,06 m³ sem o 430610. | R39: =HYPERLINK("#'Painel'!B71","→ 71") -> → 71
B40: 44 | C40: 432010 | D40: Esc. carga e transp. 3a. cat. 1600-2000m | E40: m³ | F40: 763.27 | G40: 763.27 | H40: =(Painel!$L$68)*0.05301071 -> 926.49529 | I40: =IF(H40="","",H40-F40) -> 163.22529 | J40: =IF(OR(H40="",F40=0),"",H40/F40-1) -> 0.21385001 | K40: 53.74 | L40: 41018.12 | M40: =IF(H40="",F40*K40,H40*K40) -> 49789.857 | N40: =M40-L40 -> 8771.7371 | O40: =IF(F40=0,"Sem qtd. no contrato",IF(ABS(H40/F40-1)<=0.02,"Confere (±2%)",IF(H40>F40,"Projeto maior","Projeto menor"))) -> Projeto maior | P40: Projeto por estaca – grupo repartido na proporção do contrato · corte 3ª cat. do projeto × participação da faixa de DMT no contrato · memória: Quadro de terraplenagem (mesma faixa de DMT) | Q40: Corte 3ª cat. por estaca: 17.477,51 m³ contra 14.398,41 m³ das faixas do contrato (+21,4%), repartido na proporção do contrato. Note que o quadro soma 12.986,06 m³ sem o 430610. | R40: =HYPERLINK("#'Painel'!B72","→ 72") -> → 72
B41: 45 | C41: 433010 | D41: Esc. carga e transp. 3a. cat. 2000-3000m | E41: m³ | F41: 1070.38 | G41: 1070.38 | H41: =(Painel!$L$68)*0.07434015 -> 1299.2808 | I41: =IF(H41="","",H41-F41) -> 228.90083 | J41: =IF(OR(H41="",F41=0),"",H41/F41-1) -> 0.21385006 | K41: 57.73 | L41: 61793.03 | M41: =IF(H41="",F41*K41,H41*K41) -> 75007.482 | N41: =M41-L41 -> 13214.452 | O41: =IF(F41=0,"Sem qtd. no contrato",IF(ABS(H41/F41-1)<=0.02,"Confere (±2%)",IF(H41>F41,"Projeto maior","Projeto menor"))) -> Projeto maior | P41: Projeto por estaca – grupo repartido na proporção do contrato · corte 3ª cat. do projeto × participação da faixa de DMT no contrato · memória: Quadro de terraplenagem (mesma faixa de DMT) | Q41: Corte 3ª cat. por estaca: 17.477,51 m³ contra 14.398,41 m³ das faixas do contrato (+21,4%), repartido na proporção do contrato. Note que o quadro soma 12.986,06 m³ sem o 430610. | R41: =HYPERLINK("#'Painel'!B73","→ 73") -> → 73
B42: 46 | C42: 434010 | D42: Esc. carga e transp. 3a. cat. 3000-4000m | E42: m³ | F42: 8445.73 | G42: 8445.73 | H42: =(Painel!$L$68)*0.5865738 -> 10251.85 | I42: =IF(H42="","",H42-F42) -> 1806.1203 | J42: =IF(OR(H42="",F42=0),"",H42/F42-1) -> 0.21385012 | K42: 62.3 | L42: 526168.97 | M42: =IF(H42="",F42*K42,H42*K42) -> 638690.28 | N42: =M42-L42 -> 112521.31 | O42: =IF(F42=0,"Sem qtd. no contrato",IF(ABS(H42/F42-1)<=0.02,"Confere (±2%)",IF(H42>F42,"Projeto maior","Projeto menor"))) -> Projeto maior | P42: Projeto por estaca – grupo repartido na proporção do contrato · corte 3ª cat. do projeto × participação da faixa de DMT no contrato · memória: Quadro de terraplenagem (mesma faixa de DMT) | Q42: Corte 3ª cat. por estaca: 17.477,51 m³ contra 14.398,41 m³ das faixas do contrato (+21,4%), repartido na proporção do contrato. Note que o quadro soma 12.986,06 m³ sem o 430610. | R42: =HYPERLINK("#'Painel'!B74","→ 74") -> → 74
B43: 47 | C43: 404300 | D43: Espalhamento e conformação de bota-fora | E43: m³ | F43: 75087.01 | G43: 75087.01 | H43: =Painel!$L$76 -> 75884.541 | I43: =IF(H43="","",H43-F43) -> 797.53062 | J43: =IF(OR(H43="",F43=0),"",H43/F43-1) -> 0.010621419 | K43: 0.87 | L43: 65325.69 | M43: =IF(H43="",F43*K43,H43*K43) -> 66019.55 | N43: =M43-L43 -> 693.86034 | O43: =IF(F43=0,"Sem qtd. no contrato",IF(ABS(H43/F43-1)<=0.02,"Confere (±2%)",IF(H43>F43,"Projeto maior","Projeto menor"))) -> Confere (±2%) | P43: Projeto por estaca · volume de limpeza + solo mole removido · memória: Quadro de terraplenagem 1.1.42 | Q43: Quadro = contrato. Por estaca (limpeza + solo mole removido) dá 75.884,54 m³ (+1,1%). | R43: =HYPERLINK("#'Painel'!B76","→ 76") -> → 76
...

Sheet Discrepâncias
B2: DISCREPÂNCIAS ENCONTRADAS NA ANÁLISE DA PLANILHA, DO CONTRATO E DOS PROJETOS – PR-990
B3: Valores a preço do contrato, trecho inteiro. Colunas de contrato, memória e projeto em unidades do serviço; impacto (R$) = consumo real − contrato, vindo da aba Contrato × Projeto (atualiza com as premissas).
B5: 1 · CONTRATO × PROJETO – PRINCIPAIS DIVERGÊNCIAS DE QUANTIDADE
B6: # | C6: Disciplina | D6: Código / item | E6: Serviço | F6: Contrato | G6: Memória (quadro) | H6: Consumo real | I6: Impacto (R$) | J6: Descrição da discrepância | K6: Tratamento no painel / ação sugerida
B7: 1 | C7: Ligantes | D7: 589000 | E7: CAP 50/70 (t) | F7: ='Contrato × Projeto'!F64 -> 1068.62 | G7: 1068.64 | H7: ='Contrato × Projeto'!H64 -> 857.69152 | I7: ='Contrato × Projeto'!N64 -> -1170178.5 | J7: Teor de CAP: contrato e memória a 5,7%; o executado é 4,8%. Somado ao CBUQ apurado por estaca (−4,7%), o CAP cai 19,7%. | K7: Painel usa a premissa editável H6 (teor executado). Ajustar o 589000 por apostilamento/aditivo de quantidades.
B8: 2 | C8: Drenagem – dispositivos | D8: 605300 · 602000 · 603000 · 603300 | E8: Concreto, formas e aço dos dispositivos | F8: vários | H8: vários | I8: ='Contrato × Projeto'!N127+'Contrato × Projeto'!N133+'Contrato × Projeto'!N123+'Contrato × Projeto'!N124+'Contrato × Projeto'!N126+'Contrato × Projeto'!N129 -> -841134.96 | J8: Pelos consumos unitários dos detalhes DR-4 × quantidades das notas de serviço, o concreto fck 15 é 15% do contrato (139,48 × 920,67 m³), as formas 40% e o CA-60 25%; o CA-50 é 2,3×. A proporção CA-50/CA-60 do contrato é a inversa da dos detalhes. | K8: Painel valora pelos consumos dos detalhes. Pedir à projetista a memória dos insumos dos dispositivos.
B9: 3 | C9: Obras complementares | D9: 831000 | E9: Cerca de 4 fios | F9: ='Contrato × Projeto'!F231 -> 15906.82 | G9: 27243.64 | H9: ='Contrato × Projeto'!H231 -> 27243.64 | I9: ='Contrato × Projeto'!N231 -> 488730.31 | J9: A Tab. 78 e a tabela por estaca da memória somam 27.243,64 m; o contrato tem 15.906,82 m (+11.336,82 m). | K9: Painel usa a memória por estaca. Rever o quantitativo contratual (provável omissão de um lado ou de trechos).
B10: 4 | C10: Drenagem | D10: 653400 | E10: Sarjeta trapezoidal tipo 3 + STB 01 | F10: ='Contrato × Projeto'!F110 -> 109 | H10: ='Contrato × Projeto'!H110 -> 1767 | I10: ='Contrato × Projeto'!N110 -> 204199.28 | J10: Contrato 109 m (só SZC 03). A sarjeta de borda de aterro STB 01 (1.659 m nas notas de serviço) não tem item próprio e é medida no 653400. | K10: Painel soma SZC 03 + STB 01 no 653400. Criar item para a STB 01 ou formalizar a equivalência de preço.
B11: 5 | C11: Pavimentação | D11: 530200 · 531100 · 570400 | E11: Bica corrida, BGS e CBUQ | F11: vários | H11: vários | I11: ='Contrato × Projeto'!N50+'Contrato × Projeto'!N51+'Contrato × Projeto'!N52 -> -916652.93 | J11: O contrato segue a Tab. 71 da memória; o cálculo por estaca (larguras medidas × espessuras PV-2) dá −2,2% (bica), −5,5% (BGS) e −4,7% (CBUQ). | K11: Painel usa o cálculo por estaca. Conferir as larguras dos trechos de interseção e acessos.
B12: 6 | C12: Terraplenagem | D12: 430610 · 401100 · 403000 | E12: Parcela de 1.412,35 m³ repetida | F12: vários | H12: vários | I12: ='Contrato × Projeto'!N38+'Contrato × Projeto'!N16+'Contrato × Projeto'!N17 -> -7212.6747 | J12: 1.412,35 m³ (preenchimento de rebaixo com material de 3ª, quadro 1.1.33) aparecem no contrato três vezes: como transporte 3ª cat. 400–600 m (faixa que não existe no quadro), somados à compactação 100% PN (102.477,69 × 101.065,34) e à compactação em 3ª cat. (18.294,23 × 16.881,88). | K12: Painel usa o corte por estaca e o quadro. Excluir a duplicidade no contrato.
B13: 7 | C13: Terraplenagem | D13: 430410 a 434010 | E13: Transporte de 3ª categoria | F13: ='Contrato × Projeto'!F37+'Contrato × Projeto'!F38+'Contrato × Projeto'!F39+'Contrato × Projeto'!F40+'Contrato × Projeto'!F41+'Contrato × Projeto'!F42 -> 14398.41 | H13: =N('Contrato × Projeto'!H37)+N('Contrato × Projeto'!H38)+N('Contrato × Projeto'!H39)+N('Contrato × Projeto'!H40)+N('Contrato × Projeto'!H41)+N('Contrato × Projeto'!H42) -> 17477.512 | I13: ='Contrato × Projeto'!N37+'Contrato × Projeto'!N38+'Contrato × Projeto'!N39+'Contrato × Projeto'!N40+'Contrato × Projeto'!N41+'Contrato × Projeto'!N42 -> 176493.05 | J13: Corte em 3ª cat. por estaca (REV04): 17.477,51 m³; faixas do contrato: 14.398,41 m³ (+21,4%). O quadro soma 12.986,06 m³. | K13: Painel reparte o corte de 3ª por estaca na proporção das faixas do contrato.
B14: 8 | C14: Terraplenagem | D14: 495161 | E14: Fundação de aterro com rachão | F14: ='Contrato × Projeto'!F46 -> 28703.95 | G14: 27235.29 | H14: ='Contrato × Projeto'!H46 -> 27235.294 | I14: ='Contrato × Projeto'!N46 -> -249319.04 | J14: Quadro: 25.822,95 + 1.412,35 = 27.235,29 m³ (igual ao apurado por estaca); contrato 28.703,95 (+1.468,66). | K14: Painel usa a REV04.
B15: 9 | C15: Paisagismo | D15: 800000 · 800100 | E15: Enleivamento e hidrossemeadura | F15: vários | H15: vários | I15: ='Contrato × Projeto'!N266+'Contrato × Projeto'!N268 -> -321625.9 | J15: Tab. 76: enleivamento 111.056,76 m² (com canteiro e DME) e hidrossemeadura 39.601,86 m²; contrato 128.450 e 47.522 m². A Tab. 76 tem adubação de cobertura (38.927,59 m²) sem item no contrato. | K15: Painel usa a memória por estaca.
B16: 10 | C16: Drenagem – canais | D16: 860200 · 860023 · 860150 | E16: Gabiões e colchão dos canais | F16: vários | H16: vários | I16: ='Contrato × Projeto'!N138+'Contrato × Projeto'!N139+'Contrato × Projeto'!N140 -> -403879.97 | J16: Canais DR-5 (seção tipo × extensão): gabião h 0,50 166,5 m³ (contrato 360,5), colchão 6.266 m² (6.854), gabião h 1,00 863 m³ (902). | K16: Painel usa as pranchas DR-5.
B17: 11 | C17: Drenagem | D17: 602200 · 800000 · 696420 | E17: Escoramento, enleivamento de valas e PEAD | F17: vários | H17: vários | I17: ='Contrato × Projeto'!N99+'Contrato × Projeto'!N95+'Contrato × Projeto'!N135 -> -202338.63 | J17: Notas de serviço: escoramento 587,77 m² (contrato 1.808), enleivamento das valas 897,90 m² (3.412), PEAD das bacias 57 m (1.539). | K17: Painel usa as notas de serviço.
B18: 12 | C18: Drenagem | D18: 607000 · 690051 | E18: Manta e brita dos drenos sub-superficiais | F18: vários | H18: vários | I18: ='Contrato × Projeto'!N136+'Contrato × Projeto'!N137 -> 95829.446 | J18: DSS 02/04 × detalhe DR-4-0016 (2,15 m²/m e 0,16 m³/m): 6.545,29 m² e 487,09 m³ – o dobro do contrato. O DSS 04 (1.450,47 m) não tem item próprio. | K18: Painel valora pelo detalhe. Confirmar se o contrato considerou só o DSS 02.
B19: 13 | C19: Galerias | D19: 730000 · 792140 · 711000 | E19: Insumos das galerias celulares | F19: vários | H19: vários | I19: ='Contrato × Projeto'!N196+'Contrato × Projeto'!N197+'Contrato × Projeto'!N202+'Contrato × Projeto'!N199+'Contrato × Projeto'!N200+'Contrato × Projeto'!N201 -> -190780.66 | J19: Tabelas DNIT/DER-PR (DR-4-0039 a 0056) dão aço −8,1%, concreto −14,2%, formas −10,1%; o escoramento (só a seção 3,00 × 4,00 traz) é +17,8%. | K19: Painel usa as tabelas das galerias.
B20: 14 | C20: Drenagem | D20: 691104 · 622100 · 611300 | E20: PV, bocas de dreno e BSTC Ø 1,20 | F20: vários | H20: vários | I20: ='Contrato × Projeto'!N134+'Contrato × Projeto'!N79+'Contrato × Projeto'!N86 -> -92915.91 | J20: Notas de serviço: 5 PV 2 (contrato 36), 70 bocas BSD 02 (58), 183,67 m de BSTC Ø 1,20 (228). | K20: Painel usa as notas de serviço DR-9.
B21: 15 | C21: Interferências | D21: 308 a 312 | E21: Remanejamento da rede de água (DN 75) | F21: vários | H21: vários | I21: ='Contrato × Projeto'!N348+'Contrato × Projeto'!N349+'Contrato × Projeto'!N350+'Contrato × Projeto'!N351+'Contrato × Projeto'!N352 -> 1665474.6 | J21: O projeto de interferências (IT-2-0001) tem 4.808 m de tubulação Ø 85 mm (PVC DN 75) a remanejar, de 229+1 a 465+14 LE; o contrato prevê 1.150 m. Enleivamento, escavação, lastro e reaterro foram levados na mesma proporção (consumo por metro do contrato). | K21: Painel usa a extensão do projeto. Confirmar com a SANEPAR a extensão real e a seção de vala – os consumos do contrato (6 m³/m de escavação) parecem altos para DN 75.
B22: 16 | C22: Sinalização | D22: 823000 | E22: Defensa metálica | F22: ='Contrato × Projeto'!F272 -> 5039 | G22: 5039 | H22: ='Contrato × Projeto'!H272 -> 4947 | I22: ='Contrato × Projeto'!N272 -> -49774.76 | J22: Tab. 74: 4.735 + 304 (terminal abatido) = 5.039 m = contrato. A tabela por estaca da memória soma 4.947 m, com linhas incoerentes (370 m em 52 m de estaca; 92 m em 315 m). | K22: Painel usa a tabela por estaca (4.947 m). Pedir a correção da tabela.
B23: 17 | C23: Contenções | D23: 607000 | E23: Geotêxtil dos muros (CO-2) | F23: ='Contrato × Projeto'!F190 -> 1380 | G23: 1215 | H23: ='Contrato × Projeto'!H190 -> 1215 | I23: ='Contrato × Projeto'!N190 -> -1671.45 | J23: O quadro de materiais do CO-2 imprime 1.380 m², mas as parcelas somam 475 + 740 = 1.215 m² (erro de soma levado ao contrato). | K23: Painel usa 1.215 m².
H24: Soma | I24: =SUM(I7:I23) -> -1816758.7 | J24: ="Diferença total real − contrato (todos os itens): R$ "&FIXED('Contrato × Projeto'!N359,2) -> Diferença total real − contrato (todos os itens): R$ -1,986,016.05
B26: 2 · SERVIÇOS QUANTIFICADOS NO PROJETO SEM ITEM NA PLANILHA CONTRATUAL
B27: # | C27: Disciplina | D27: Fonte | E27: Serviço | F27: Un | G27: — | H27: Qtd. projeto | I27: Estimativa (R$) | J27: Observação | K27: Preço de referência usado na estimativa
B28: 1 | C28: Drenagem | D28: DR-9 (notas de serviço) | E28: Sarjeta triangular de concreto STC 05 | F28: m | H28: =Painel!$L$120 -> 1928 | I28: =H28*176.99 -> 341236.72 | J28: 1.928 m nas notas de serviço; nenhum item de sarjeta STC 05 no contrato. | K28: 650000 – sarjeta triangular tipo 1 (similar) · R$ 176,99
B29: 2 | C29: Drenagem | D29: DR-9 (notas de serviço) | E29: Sarjeta triangular de concreto STC 11 | F29: m | H29: =Painel!$L$121 -> 1273 | I29: =H29*176.99 -> 225308.27 | J29: 1.273 m nas notas de serviço; nenhum item de sarjeta STC 11 no contrato. | K29: 650000 – sarjeta triangular tipo 1 (similar) · R$ 176,99
B30: 3 | C30: Drenagem | D30: DR-9 / DR-4-0016 | E30: Dreno sub-superficial DSS 04 | F30: m | H30: =Painel!$L$136 -> 1450.47 | I30: =H30*25.59 -> 37117.527 | J30: O contrato tem só o 644200 (DSS 02, 1.594 m); o DSS 04 não tem item. | K30: 644200 – dreno sub-superficial tipo 2 (similar) · R$ 25,59
B31: 4 | C31: Drenagem – canais | D31: DR-5-0002 a 0011 | E31: Lastro de rachão e = 0,40 m dos canais | F31: m³ | H31: =Painel!$L$190 -> 2752.8 | I31: =H31*169.76 -> 467315.33 | J31: Sem item de rachão no grupo Dispositivos. | K31: 495161 – fundação de aterro com rachão (similar) · R$ 169,76
B32: 5 | C32: Drenagem – canais | D32: DR-5-0002 a 0011 | E32: Geotêxtil MacTex dos canais | F32: m² | H32: =Painel!$L$191 -> 7654 | I32: =H32*10.13 -> 77535.02 | J32: Se o 607000 do grupo Dispositivos for só dos drenos (6.545 m² no projeto), o geotêxtil dos canais fica sem item. | K32: 607000 – geotêxtil não tecido · R$ 10,13
B33: 6 | C33: Sinalização | D33: Tab. 74 / SI-1-0016 | E33: Barreira New Jersey simples (813000) | F33: m | H33: 64 | I33: – | J33: Quantificada na memória; o contrato só tem os refletivos de barreira (801926). | K33: sem preço no contrato
B34: 7 | C34: Paisagismo | D34: Tab. 76 | E34: Adubação de cobertura (hidrossemeadura + enleivamento) | F34: m² | H34: 38927.59 | I34: – | J34: 11.880,56 m² (hidrossemeadura) + 27.047,03 m² (enleivamento). | K34: sem preço no contrato
B35: 8 | C35: Obras complementares | D35: Tab. 78 item 22 | E35: Travessia elevada para pedestres | F35: un | H35: 1 | I35: – | J35: Contrato só tem o piso tátil das travessias (834907, 10 m²). | K35: sem preço no contrato
B36: 9 | C36: Contenções | D36: CO-2 (revisão Terramesh) | E36: Rachão para preparação da base dos muros | F36: m³ | H36: =Painel!$L$344 -> 430.5 | I36: =H36*169.76 -> 73081.68 | J36: Quadro de materiais do CO-2: 430,50 m³. | K36: 495161 – fundação de aterro com rachão (similar) · R$ 169,76
H37: Soma | I37: =SUM(I28:I36) -> 1221594.5 | J37: Estimativa só para dimensionar o impacto (preço de item similar do contrato); não entra no total do painel.
B39: 3 · INCONSISTÊNCIAS INTERNAS DAS MEMÓRIAS E PRANCHAS
B40: # | C40: Disciplina | D40: Documento | E40: Assunto | F40: — | G40: — | H40: — | I40: — | J40: Descrição | K40: Efeito no painel
B41: 1 | C41: Terraplenagem | D41: Tomo II – quadro 1.2.2 | E41: Tela de proteção de talude | J41: Linha geral 2.409,47 kg e coluna total 2.928,56 kg no mesmo item; a planilha de distribuição usa 2.928,555 kg. O contrato adotou 2.409,47. | K41: Painel usa 2.409,47 (= contrato).
B42: 2 | C42: Pavimentação | D42: Tomo II – Tab. 70 × Tab. 71 | E42: Taxas de ligantes | J42: Tab. 70 indica RR-1C 0,00045 t/m² (→ 72,78 t), mas a Tab. 71 usa 0,50 kg/m² (80,87 t). A EAI vem em l/m² na Tab. 70 e em kg/m² na Tab. 71. | K42: Taxas são premissas editáveis (H7, H8).
B43: 3 | C43: Pavimentação | D43: Tomo II – Tab. 71 × contrato | E43: Imprimação | J43: Imprimação 161.734 m² na memória e 161.756 m² no contrato (+22 m²); a pintura de ligação, de mesma área, ficou 161.734. | K43: —
B44: 4 | C44: Contenções | D44: CO-2 – quadro resumo | E44: Geotêxtil | J44: Total impresso 1.380 m²; parcelas 740 + 475 = 1.215 m². | K44: Painel usa 1.215 m².
...

Sheet Leia-me
A1: Base de volumes de pavimentação – PR-990, Est. 0+0,00 a 642+15,817
A2: Fontes: plantas de pavimentação PV-1-0001 a 0009 (larguras medidas por estaca) e seções tipo PV-2-0001 e 0002 (camadas, espessuras, alargamentos e segmentos).
A4: Como a base funciona
A5: 1) Aba "Estacas": largura W do CBUQ acabado em cada estaca (20 m) e nos limites de segmento. Em zona urbana o passeio foi separado de W. As áreas de cada camada são calculadas por fórmula a partir de W e dos parâmetros.
A6: 2) Aba "Parâmetros": espessura, alargamento do topo e talude de cada camada, tirados do Detalhe "A" das seções tipo. Cada camada fica mais larga que a de cima: CBUQ com borda a 45°, BGS começando 10 cm além do bordo do CBUQ, sub-base 10 cm além do pé da BGS, reforço 10 cm além do pé da sub-base.
A7: Larguras resultantes para W = 11,00 m: CBUQ 11,00 (topo) / 11,10 (base); BGS 11,20 / 11,52; sub-base 11,72 / 12,12; reforço 12,32 / 12,92.
A8: 3) Aba "Volumes por intervalo": volume entre cada par de estacas consecutivas pelo método das áreas médias. Cada intervalo recebe o segmento/seção tipo do seu ponto médio.
A9: 4) Aba "Resumo por segmento": soma por segmento de seção tipo (SUMIFS) e total geral.
A11: Ajustes feitos na largura medida
A12: • Bocas de acesso: linhas do pavimento do acesso captadas na seção foram descartadas (o acesso tem estrutura própria – 15 cm de BGS + EAI, nota 1 das pranchas – e não entra nesta base).
A13: • Estacas onde a borda de um acesso corta a seção junto ao eixo, ou com pico isolado na boca do acesso: largura interpolada entre as estacas vizinhas (coluna "Origem da largura").
A14: • Interseção 01 (Barra dos Andrades): largura limitada a 18,40 m (seção tipo 02); o pavimento da via transversal fica fora.
... A72: • Linhas em itálico cinza são quantidades de projeto rateadas (o projeto só dá o total). Bocas de bueiro do projeto estimadas em 2 por bueiro. Linhas com quantidade zero ficam esmaecidas.

Sheet Parâmetros
A1: PARÂMETROS DAS CAMADAS – Seções tipo DE-E-PR-990-000-012-2-PV-2-0001/0002 (Detalhe "A")
A3: Item | B3: Camada / serviço | C3: Espessura (m) | D3: Alargamento do topo da camada, por lado, além do bordo do CBUQ acabado (m) | E3: Talude da borda (H:V) | F3: Unidade de medição | G3: Especificação | H3: Fonte / observação
A4: C1 | B4: CBUQ Faixa C – asfalto convencional | C4: 0.05 | D4: 0 | E4: 1 | F4: m³ | G4: DER-ES-TE-21-23 | H4: Topo = largura acabada medida na planta; borda a 45° (Detalhe A: 5 cm)
A5: C2 | B5: Base – BGS 100% PM | C5: 0.16 | D5: 0.1 | E5: 1 | F5: m³ | G5: DER-ES-TE-05-23 | H5: Detalhe A: 5+5 cm além do bordo do CBUQ no topo; borda 1:1 (16 cm)
A6: C3 | B6: Sub-base – bica corrida | C6: 0.2 | D6: 0.36 | E6: 1 | F6: m³ | G6: DER-ES-TE-06-23 | H6: Detalhe A: topo 10 cm além do pé da BGS (0,10+0,16+0,10); borda 1:1 (20 cm)
A7: C4 | B7: Reforço do subleito – bica corrida (2 x 15 cm) | C7: 0.3 | D7: 0.66 | E7: 1 | F7: m³ | G7: DER-ES-TE-06-23 | H7: Detalhe A: topo 10 cm além do pé da sub-base (0,36+0,20+0,10); borda 1:1 (30 cm)
A8: C5 | B8: Imprimação asfáltica – EAI | D8: 0.1 | F8: m² | G8: DER-ES-TE-17-23 | H8: Aplicada no topo da BGS (largura = CBUQ + 2 x 0,10)
A9: C6 | B9: Pintura de ligação – RR-1C | D9: 0.1 | F9: m² | G9: DER-ES-TE-17-23 | H9: Representada na seção sobre a imprimação, mesma largura (CBUQ + 2 x 0,10)
A10: C7 | B10: Regularização e compactação do subleito 100% PN | D10: 0.96 | F10: m² | G10: DER-ES-TE-01-23 | H10: Largura do pé do reforço (0,66 + 0,30 por lado)
A11: C8 | B11: Bloco de concreto (paver) – passeio | C11: 0.06 | D11: 0 | F11: m³ | G11: ABNT NBR 9050/2023 | H11: Só seções urbanas (T07, T08, T09); largura do passeio medida na planta
A12: C9 | B12: Colchão de pó de pedra – passeio | C12: 0.05 | D12: 0 | F12: m³ | G12: ABNT NBR 9050/2023 | H12: Idem
A13: C10 | B13: Remoção mecanizada de pavimento existente (T09) | C13: 0.41 | D13: 6.5 | F13: m³ | G13: DER-ES-TE-27-23 | H13: ESTIMATIVA: largura total (coluna D) e profundidade (coluna C) medidas na hachura da seção tipo 09 (≈6,5 m x 0,41 m). Ajustar com levantamento do pavimento existente.
A14: C11 | B14: Densidade do CBUQ (para tonelagem) | C14: 2.4 | F14: t/m³ | H14: Valor de referência – substituir pela densidade do projeto de mistura
A16: Células amarelas (azul) são entradas editáveis; todas as áreas e volumes das outras abas se recalculam.
A17: Área de cada camada (m²) = e × (W + 2a + e × t), onde W = largura do CBUQ acabado, e = espessura, a = alargamento do topo, t = talude.
A18: Volume entre duas estacas = extensão × média das áreas (método das áreas médias).
A21: TERRAPLENAGEM
B22: Espessura média de limpeza (área = volume / espessura) | C22: 0.2 | H22: Planilha VOLUMES DE TERRAPLENAGEM REV04 – Resumo: área 232.329,70 m² x 0,20 = 46.465,94 m³

Sheet Resumo por segmento
A1: Segmento | B1: Seção tipo | C1: Descrição | D1: Estaca inicial | E1: Estaca final | F1: Extensão (m) | G1: CBUQ (m³) | H1: CBUQ (t) | I1: BGS (m³) | J1: Sub-base (m³) | K1: Reforço (m³) | L1: Imprimação EAI (m²) | M1: Pintura RR-1C (m²) | N1: Regularização subleito (m²) | O1: Paver (m³) | P1: Pó de pedra (m³) | Q1: Paver / passeio (m²) | R1: Remoção pav. existente (m³)
A2: S01 | B2: T01 | C2: Linha geral c/ acostamento LE e LD | D2: 0+0,00 | E2: 319+0,00 | F2: =SUMIFS('Volumes por intervalo'!$C$2:$C$649,'Volumes por intervalo'!$D$2:$D$649,A2) -> 6380 | G2: =SUMIFS('Volumes por intervalo'!$H$2:$H$649,'Volumes por intervalo'!$D$2:$D$649,A2) -> 3607.6 | H2: =SUMIFS('Volumes por intervalo'!$I$2:$I$649,'Volumes por intervalo'!$D$2:$D$649,A2) -> 8658.24 | I2: =SUMIFS('Volumes por intervalo'!$J$2:$J$649,'Volumes por intervalo'!$D$2:$D$649,A2) -> 11860.768 | J2: =SUMIFS('Volumes por intervalo'!$K$2:$K$649,'Volumes por intervalo'!$D$2:$D$649,A2) -> 15540.52 | K2: =SUMIFS('Volumes por intervalo'!$L$2:$L$649,'Volumes por intervalo'!$D$2:$D$649,A2) -> 24650.58 | L2: =SUMIFS('Volumes por intervalo'!$M$2:$M$649,'Volumes por intervalo'!$D$2:$D$649,A2) -> 73109 | M2: =SUMIFS('Volumes por intervalo'!$N$2:$N$649,'Volumes por intervalo'!$D$2:$D$649,A2) -> 73109 | N2: =SUMIFS('Volumes por intervalo'!$O$2:$O$649,'Volumes por intervalo'!$D$2:$D$649,A2) -> 84082.6 | O2: =SUMIFS('Volumes por intervalo'!$P$2:$P$649,'Volumes por intervalo'!$D$2:$D$649,A2) -> 0 | P2: =SUMIFS('Volumes por intervalo'!$Q$2:$Q$649,'Volumes por intervalo'!$D$2:$D$649,A2) -> 0 | Q2: =SUMIFS('Volumes por intervalo'!$R$2:$R$649,'Volumes por intervalo'!$D$2:$D$649,A2) -> 0 | R2: =SUMIFS('Volumes por intervalo'!$S$2:$S$649,'Volumes por intervalo'!$D$2:$D$649,A2) -> 0
